ValueError                                Traceback (most recent call last)
~\AppData\Local\Temp\2\ipykernel_29620\3079990056.py in <cell line: 47>()
     45 
     46 # Train the model with validation
---> 47 history = model.fit(X_train, y_train, epochs=50, batch_size=32, validation_split=0.2)
     48 
     49 # Assuming you have test data stored in X_test (3D array with shape (number of samples, 14, 26))

c:\users\v807880\jpy\lib\site-packages\keras\utils\traceback_utils.py in error_handler(*args, **kwargs)
     68             # To get the full stack trace, call:
     69             # `tf.debugging.disable_traceback_filtering()`
---> 70             raise e.with_traceback(filtered_tb) from None
     71         finally:
     72             del filtered_tb

c:\users\v807880\jpy\lib\site-packages\keras\engine\training.py in tf__train_function(iterator)
     13                 try:
     14                     do_return = True
---> 15                     retval_ = ag__.converted_call(ag__.ld(step_function), (ag__.ld(self), ag__.ld(iterator)), None, fscope)
     16                 except:
     17                     do_return = False

ValueError: in user code:

    File "c:\users\v807880\jpy\lib\site-packages\keras\engine\training.py", line 1160, in train_function  *
        return step_function(self, iterator)
    File "c:\users\v807880\jpy\lib\site-packages\keras\engine\training.py", line 1146, in step_function  **
        outputs = model.distribute_strategy.run(run_step, args=(data,))
    File "c:\users\v807880\jpy\lib\site-packages\keras\engine\training.py", line 1135, in run_step  **
        outputs = model.train_step(data)
    File "c:\users\v807880\jpy\lib\site-packages\keras\engine\training.py", line 993, in train_step
        y_pred = self(x, training=True)
    File "c:\users\v807880\jpy\lib\site-packages\keras\utils\traceback_utils.py", line 70, in error_handler
        raise e.with_traceback(filtered_tb) from None
    File "c:\users\v807880\jpy\lib\site-packages\keras\engine\input_spec.py", line 295, in assert_input_compatibility
        raise ValueError(

    ValueError: Input 0 of layer "sequential_94" is incompatible with the layer: expected shape=(None, 14, 26), found shape=(None, 364)
