ValueError: Exception encountered when calling layer "sequential_8" "                 f"(type Sequential).
    
    Input 0 of layer "dense_24" is incompatible with the layer: expected axis -1 of input shape to have value 14, but received input with shape (None, 14, 24)
    
    Call arguments received by layer "sequential_8" "                 f"(type Sequential):
      • inputs=tf.Tensor(shape=(None, 14, 24), dtype=float32)
      • training=True
      • mask=None


model.add(LSTM(32, input_shape=(time_steps, len(features))))


from keras.models import Sequential
from keras.layers import Conv1D, MaxPooling1D, Flatten, Dense

model = Sequential()
model.add(Conv1D(32, 3, activation='relu', input_shape=(time_steps, len(features))))
model.add(MaxPooling1D())
model.add(Flatten())
model.add(Dense(16, activation='relu'))
model.add(Dense(1, activation='tanh'))

